<?xml version="1.7" ?>
<sdf version="1.7">

  <model name="WheeBBot_sdf">

    <pose> 0 0 0 0 0 0 </pose>

    <static>false</static>

    <!-Links -->

    <link name='left_wheel'>
          <pose> 0 0.14 0.06 0 0 0 </pose>
          <inertial>
            <pose>0 0 0 0 0 0 </pose>
            <mass>0.6</mass>
            <inertia>
              <ixx>0.0005</ixx>
              <ixy>0</ixy>
              <ixz>0</ixz>
              <iyy>0.001</iyy>
              <iyz>0</iyz>
              <izz>0.0005</izz>
            </inertia>
          </inertial>
          <collision name='collision_left_wheel'>
            <max_contacts> 10 </max_contacts> 
            <pose>0 0 0 1.5707963267948966 0 0  </pose>
            <geometry>
              <cylinder>
                <radius>0.06 </radius>
                <length>0.01</length>
              </cylinder>
            </geometry>
            <surface>
              <friction>
                <ode>
                  <mu>0.5</mu>
                  <mu2>0.5</mu2>
                  <!--<fdir1>1 0 0</fdir1>
                  <slip1>0.0</slip1>
                  <slip2>0.0</slip2>-->
                </ode>
                <bullet>
                  <friction>0.5</friction>
                  <friction2>0.5</friction2>
                  <!--<fdir1>0 0 0</fdir1>-->
                  <!--<slip1>0.0</slip1>-->
                  <!--<slip2>0.0</slip2>-->
                </bullet>

              </friction>

              <contact>
                <ode>
                  <!--<max_vel>100</max_vel>
                  <min_depth>0.001</min_depth>-->
                  <kp>50000000 </kp>
                  <kd>1</kd>
                </ode>
                <bullet>
                  <kp>50000000</kp>
                  <kd>1</kd>
                </bullet>
              </contact>
            </surface>
          </collision>
          <visual name='visual_left_wheel'>
            <pose>0 0 0 0 0 1.5707963267948966  </pose>
            <geometry>
              <mesh>
                <uri>model://WheeBBot_sdf/meshes/wheel_black.dae</uri>
              </mesh>
           </geometry>
          </visual>
    </link>

    <link name='right_wheel'>
          <max_contacts> 10 </max_contacts> 
          <pose> 0 -0.14 0.06 0 0 0 </pose>
          <inertial>
            <pose>0 0 0 0 0 0 </pose>
            <mass>0.6</mass>
            <inertia>
              <ixx>0.0005</ixx>
              <ixy>0</ixy>
              <ixz>0</ixz>
              <iyy>0.001</iyy>
              <iyz>0</iyz>
              <izz>0.0005</izz>
            </inertia>
          </inertial>
          <collision name='collision_right_wheel'>
            <pose>0 0 0 1.5707963267948966 0 0  </pose>
            <geometry>
              <cylinder>
                <radius>0.06 </radius>
                <length>0.01</length>
              </cylinder>
            </geometry>
            <surface>
              <friction>
                <ode>
                  <mu>0.5</mu>
                  <mu2>0.5</mu2>
                  <!--<fdir1>1 0 0</fdir1>
                  <slip1>0.0</slip1>
                  <slip2>0.0</slip2>-->
                </ode>
                <bullet>
                  <friction>0.5</friction>
                  <friction2>0.5</friction2>
                  <!--<fdir1>1 0 0</fdir1>-->
                  <!--<slip1>0.0</slip1>-->
                  <!--<slip2>0.0</slip2>-->
                </bullet>
              </friction>
              <contact>
                <ode>
                  <!--<max_vel>100</max_vel>
                  <min_depth>0.001</min_depth>-->
                  <kp>50000000</kp>
                  <kd>1</kd>
                </ode>
                <bullet>
                  <kp>50000000</kp>
                  <kd>1</kd>
                </bullet>
              </contact>
            </surface>
          </collision>
          <visual name='visual_right_wheel'>
            <pose>0 0 0 0 0 -1.5707963267948966  </pose>
            <geometry>
              <mesh>
                <uri>model://WheeBBot_sdf/meshes/wheel_black.dae</uri>
              </mesh>
           </geometry>
          </visual>

    </link>

    <link name='left_leg_link'>
        <pose relative_to='left_wheel'> 0 -0.03500000000000002 0.15 0 1.5707963267948966 0 </pose>
        <inertial>
          <pose>0 0 0 0 0 0 </pose>
          <mass>0.1944</mass>
          <inertia>
            <ixx>1.296e-05</ixx>
            <ixy>0.0</ixy>
            <ixz>0.0</ixz>
            <iyy>0.0014644799999999998</iyy>
            <iyz>0.0</iyz>
            <izz>0.0014644799999999998</izz>
          </inertia>
        </inertial>
        <collision name='collision_left_leg'>
          <pose relative_to='left_leg_link' >0 -0.01 0 0 0 0  </pose>
          <geometry>
            <box>
              <size> 0.3 0.02 0.02 </size>
            </box>
          </geometry>
        </collision>
    </link>

    <link name='right_leg_link'>
          <pose relative_to='right_wheel'> 0 0.03500000000000002 0.15 0 1.5707963267948966 0 </pose>
          <inertial>
            <pose>0 0 0 0 0 0 </pose>
            <mass>0.1944</mass>
            <inertia>
              <ixx>1.296e-05</ixx>
              <ixy>0.0</ixy>
              <ixz>0.0</ixz>
              <iyy>0.0014644799999999998</iyy>
              <iyz>0.0</iyz>
              <izz>0.0014644799999999998</izz>
            </inertia>
          </inertial>
          <collision name='collision_right_leg'>
            <pose relative_to='right_leg_link'>0 0.01 0 0 0 0  </pose>
            <geometry>
              <box>
                <size> 0.3 0.02 0.02 </size>
              </box>
            </geometry>
          </collision>
          
    </link>

    <link name='frame_link'>
        <pose relative_to='right_leg_link'> -0.22999999999999998 0.105 0 3.141592653589793 0 0 </pose>
        <inertial>
          <pose> 0 0 0 0 0 0 </pose>
          <mass> 5 </mass>
          <inertia>
            <ixx>0.2</ixx>
            <ixy>0</ixy>
            <ixz>0</ixz>
            <iyy>0.1</iyy>
            <iyz>0</iyz>
            <izz>0.2</izz>
          </inertia>
        </inertial>
        <collision name='collision1'>
          <pose>0 0 0 0 0 0</pose>
          <geometry>
            <box>
              <size> 0.16 0.21 0.16 </size>
            </box>
          </geometry>
        </collision>
        <collision name='collision2'>
          <pose>-0.095 0 0 0 1.5707963267948966 0</pose>
          <geometry>
            <box>
              <size> 0.12 0.12 0.03 </size>
            </box>
          </geometry>
        </collision>
        <collision name='collision3'>
          <pose>0 0 0.095 0 0 0</pose>
          <geometry>
            <box>
              <size> 0.12 0.12 0.03 </size>
            </box>
          </geometry>
        </collision> 
        <visual name='visual_frame'>
            <pose>0.07 -0.095 0 -1.5707963267948966 0 1.5707963267948966  </pose>
            <geometry>
              <mesh>
                <uri>model://WheeBBot_sdf/meshes/full_no_knee_no_wheels.dae</uri>
              </mesh>
           </geometry>
          </visual>
        
    </link> 

    <!--Joints -->

    <joint type="revolute" name="left_wheel_hinge">
      <pose>0 0 0 0 0 0</pose>
      <child>left_wheel</child>
      <parent>left_leg_link</parent>
      <axis>
        <xyz>0 1 0</xyz>
        <dynamics>
          <!--<damping> 0 </damping>
          <spring_reference> 0 </spring_reference>
          <spring_stiffness> 0 </spring_stiffness>-->
        </dynamics>
        <limit>
          <!--<lower>  </lower>
          <upper>  </upper>
          <effort> </effort>-->
        </limit>
      </axis>
    </joint>

    <joint type="revolute" name="right_wheel_hinge">
      <pose>0 0 0 0 0 0</pose>
      <child>right_wheel</child>
      <parent>right_leg_link</parent>
      <axis>
        <xyz>0 1 0</xyz>
        <dynamics>
          <!--<damping> 0 </damping>
          <spring_reference>  </spring_reference>
          <spring_stiffness>  0 </spring_stiffness>-->
        </dynamics>
        <limit>
          <!--<lower> </lower>
          <upper> </upper>
          <effort> </effort>-->
        </limit>
      </axis>
    </joint>

    <joint type="fixed" name="left_leg2frame_joint">
      <parent>frame_link</parent>
      <child>left_leg_link</child>
    </joint>

    <joint type="fixed" name="right_leg2frame_joint">
      <parent>frame_link</parent>
      <child>right_leg_link</child>
    </joint>


  </model>
</sdf>