<?xml version="1.0" ?>
<!-- =================================================================================== -->
<!-- |    This document was autogenerated by xacro from wheebbot_full.urdf.xacro       | -->
<!-- |    EDITING THIS FILE BY HAND IS NOT RECOMMENDED                                 | -->
<!-- =================================================================================== -->
<robot name="wheebbot_full">
  <!-- Reading some parameters from a YAML config file -->
  <!-- Assigning those parameters to xacro properties -->
  <!-- Including the materials file -->
  <!-- <xacro:include filename="$(find wheebbot_description)/urdf/materials.urdf.xacro" /> -->
  <!-- joint state publisher (this way ignition gazebo publishes joint states to RViz) -->
  <gazebo>
    <plugin filename="libignition-gazebo-joint-state-publisher-system.so" name="ignition::gazebo::systems::JointStatePublisher"/>
  </gazebo>
  <!-- body -->
  <gazebo reference="body">
    <mu1>0.3</mu1>
    <mu2>0.3</mu2>
    <kp>1000000.0</kp>
    <kd>0.0</kd>
  </gazebo>
  <!-- right wheel -->
  <gazebo reference="right_wheel">
    <mu1>0.5</mu1>
    <mu2>0.5</mu2>
    <kp>1000000.0</kp>
    <kd>0.0</kd>
    <maxContacts>10</maxContacts>
  </gazebo>
  <!-- left wheel -->
  <gazebo reference="left_wheel">
    <mu1>0.5</mu1>
    <mu2>0.5</mu2>
    <kp>1000000.0</kp>
    <kd>0.0</kd>
    <maxContacts>10</maxContacts>
  </gazebo>
  <!-- auxiliary link on the ground (fixed wrt the robot) -->
  <link name="aux_link">
    </link>
  <joint name="aux_joint" type="fixed">
    <origin rpy="0 0 0" xyz="0 0 0.43800000000000006"/>
    <parent link="aux_link"/>
    <child link="body"/>
  </joint>
  <link name="body">
    <!-- body visual -->
    <visual>
      <origin rpy="0 0 -1.5707963267948966" xyz="0 0.095 -0.07"/>
      <geometry>
        <mesh filename="package://wheebbot_description/meshes/full_no_knee_no_wheels.dae" scale="1.0 1.0 1.0"/>
      </geometry>
    </visual>
    <!-- box -->
    <collision>
      <origin rpy="0 0 0" xyz="0 0 0"/>
      <geometry>
        <box size="0.16 0.21 0.16"/>
      </geometry>
    </collision>
    <!-- top fan collision group-->
    <!-- fan-->
    <collision>
      <origin rpy="0 0 0" xyz="0 0 0.0983"/>
      <geometry>
        <box size="0.12 0.12 0.0366"/>
      </geometry>
    </collision>
    <!-- left door handle-->
    <collision>
      <origin rpy="0 0 0" xyz="0 0.095 0.0875"/>
      <geometry>
        <box size="0.105 0.02 0.015"/>
      </geometry>
    </collision>
    <collision>
      <origin rpy="0 0 0" xyz="0 0.095 0.106"/>
      <geometry>
        <box size="0.075 0.02 0.022"/>
      </geometry>
    </collision>
    <!-- right door handle-->
    <collision>
      <origin rpy="0 0 0" xyz="0 -0.095 0.0875"/>
      <geometry>
        <box size="0.105 0.02 0.015"/>
      </geometry>
    </collision>
    <collision>
      <origin rpy="0 0 0" xyz="0 -0.095 0.106"/>
      <geometry>
        <box size="0.075 0.02 0.022"/>
      </geometry>
    </collision>
    <!-- back fan collision -->
    <collision>
      <origin rpy="0 -1.5707963267948966 0" xyz="-0.0983 0 0"/>
      <geometry>
        <box size="0.12 0.12 0.0366"/>
      </geometry>
    </collision>
    <!-- left leg -->
    <collision>
      <origin rpy="0 0 0" xyz="-0.0040000000000000036 0.095 -0.21500000000000002"/>
      <geometry>
        <box size="0.02 0.02 0.27"/>
      </geometry>
    </collision>
    <!-- left motor case -->
    <collision>
      <origin rpy="0 0 0" xyz="-0.0040000000000000036 0.0675 -0.37800000000000006"/>
      <geometry>
        <box size="0.056 0.075 0.056"/>
      </geometry>
    </collision>
    <!-- right leg -->
    <collision>
      <origin rpy="0 0 0" xyz="-0.0040000000000000036 -0.095 -0.21500000000000002"/>
      <geometry>
        <box size="0.02 0.02 0.27"/>
      </geometry>
    </collision>
    <!-- right motor case -->
    <collision>
      <origin rpy="0 0 0" xyz="-0.0040000000000000036 -0.0675 -0.37800000000000006"/>
      <geometry>
        <box size="0.056 0.075 0.056"/>
      </geometry>
    </collision>
    <inertial>
      <origin rpy="0 0.0 0" xyz="0.0 0 -0.17800000000000005"/>
      <mass value="5.0"/>
      <inertia ixx="0.020833333333333336" ixy="0.0" ixz="0.0" iyy="0.020833333333333336" iyz="0.0" izz="0.008333333333333335"/>
    </inertial>
  </link>
  <joint name="left_wheel_joint" type="revolute">
    <origin rpy="0 0 0" xyz="0 0.14 -0.37800000000000006"/>
    <parent link="body"/>
    <child link="left_wheel"/>
    <axis xyz="0 1 0"/>
    <dynamics damping="0.0" friction="0.0"/>
    <limit effort="30.0" lower="-1e+25" upper="1e+25" velocity="100.0"/>
  </joint>
  <link name="left_wheel">
    <!-- wheel visual -->
    <visual>
      <origin rpy="0 0 1.5707963267948966" xyz="0 0 0"/>
      <geometry>
        <mesh filename="package://wheebbot_description/meshes/wheel_black.dae" scale="1.0 1.0 1.0"/>
      </geometry>
    </visual>
    <collision>
      <origin rpy="1.5707963267948966 0 0" xyz="0 0 0"/>
      <geometry>
        <cylinder length="0.02" radius="0.06"/>
      </geometry>
    </collision>
    <inertial>
      <origin rpy="-1.5707963267948966 0 0" xyz="0 0 0"/>
      <mass value="0.6"/>
      <inertia ixx="0.0005599999999999998" ixy="0.0" ixz="0.0" iyy="0.0005599999999999998" iyz="0.0" izz="0.00108"/>
    </inertial>
  </link>
  <joint name="right_wheel_joint" type="revolute">
    <origin rpy="0 0 0" xyz="0 -0.14 -0.37800000000000006"/>
    <parent link="body"/>
    <child link="right_wheel"/>
    <axis xyz="0 1 0"/>
    <dynamics damping="0.0" friction="0.0"/>
    <limit effort="30.0" lower="-1e+25" upper="1e+25" velocity="100.0"/>
  </joint>
  <link name="right_wheel">
    <!-- wheel visual -->
    <visual>
      <origin rpy="0 0 -1.5707963267948966" xyz="0 0 0"/>
      <geometry>
        <mesh filename="package://wheebbot_description/meshes/wheel_black.dae" scale="1.0 1.0 1.0"/>
      </geometry>
    </visual>
    <collision>
      <origin rpy="1.5707963267948966 0 0" xyz="0 0 0"/>
      <geometry>
        <cylinder length="0.02" radius="0.06"/>
      </geometry>
    </collision>
    <inertial>
      <origin rpy="-1.5707963267948966 0 0" xyz="0 0 0"/>
      <mass value="0.6"/>
      <inertia ixx="0.0005599999999999998" ixy="0.0" ixz="0.0" iyy="0.0005599999999999998" iyz="0.0" izz="0.00108"/>
    </inertial>
  </link>
</robot>
